2025-04-04 05:48:44,718 ERROR HTTPConnectionPool(host='host.docker.internal', port=9050): Read timed out. (read timeout=5)
Traceback (most recent call last):
  File "/app/.venv/lib/python3.9/site-packages/urllib3/connectionpool.py", line 534, in _make_request
    response = conn.getresponse()
  File "/app/.venv/lib/python3.9/site-packages/urllib3/connection.py", line 516, in getresponse
    httplib_response = super().getresponse()
  File "/usr/lib/python3.9/http/client.py", line 1351, in getresponse
    response.begin()
  File "/usr/lib/python3.9/http/client.py", line 316, in begin
    version, status, reason = self._read_status()
  File "/usr/lib/python3.9/http/client.py", line 277, in _read_status
    line = str(self.fp.readline(_MAXLINE + 1), "iso-8859-1")
  File "/usr/lib/python3.9/socket.py", line 704, in readinto
    return self._sock.recv_into(b)
socket.timeout: timed out

The above exception was the direct cause of the following exception:

Traceback (most recent call last):
  File "/app/.venv/lib/python3.9/site-packages/requests/adapters.py", line 667, in send
    resp = conn.urlopen(
  File "/app/.venv/lib/python3.9/site-packages/urllib3/connectionpool.py", line 841, in urlopen
    retries = retries.increment(
  File "/app/.venv/lib/python3.9/site-packages/urllib3/util/retry.py", line 474, in increment
    raise reraise(type(error), error, _stacktrace)
  File "/app/.venv/lib/python3.9/site-packages/urllib3/util/util.py", line 39, in reraise
    raise value
  File "/app/.venv/lib/python3.9/site-packages/urllib3/connectionpool.py", line 787, in urlopen
    response = self._make_request(
  File "/app/.venv/lib/python3.9/site-packages/urllib3/connectionpool.py", line 536, in _make_request
    self._raise_timeout(err=e, url=url, timeout_value=read_timeout)
  File "/app/.venv/lib/python3.9/site-packages/urllib3/connectionpool.py", line 367, in _raise_timeout
    raise ReadTimeoutError(
urllib3.exceptions.ReadTimeoutError: HTTPConnectionPool(host='host.docker.internal', port=9050): Read timed out. (read timeout=5)

During handling of the above exception, another exception occurred:

Traceback (most recent call last):
  File "/app/service.py", line 17, in _request
    resp = requests.post(self.backend_url, json=data,
  File "/app/.venv/lib/python3.9/site-packages/requests/api.py", line 115, in post
    return request("post", url, data=data, json=json, **kwargs)
  File "/app/.venv/lib/python3.9/site-packages/requests/api.py", line 59, in request
    return session.request(method=method, url=url, **kwargs)
  File "/app/.venv/lib/python3.9/site-packages/requests/sessions.py", line 589, in request
    resp = self.send(prep, **send_kwargs)
  File "/app/.venv/lib/python3.9/site-packages/requests/sessions.py", line 703, in send
    r = adapter.send(request, **kwargs)
  File "/app/.venv/lib/python3.9/site-packages/requests/adapters.py", line 713, in send
    raise ReadTimeout(e, request=request)
requests.exceptions.ReadTimeout: HTTPConnectionPool(host='host.docker.internal', port=9050): Read timed out. (read timeout=5)
2025-04-04 05:48:44,942 ERROR 
Traceback (most recent call last):
  File "/app/.venv/lib/python3.9/site-packages/urllib3/connectionpool.py", line 534, in _make_request
    response = conn.getresponse()
  File "/app/.venv/lib/python3.9/site-packages/urllib3/connection.py", line 516, in getresponse
    httplib_response = super().getresponse()
  File "/usr/lib/python3.9/http/client.py", line 1351, in getresponse
    response.begin()
  File "/usr/lib/python3.9/http/client.py", line 316, in begin
    version, status, reason = self._read_status()
  File "/usr/lib/python3.9/http/client.py", line 277, in _read_status
    line = str(self.fp.readline(_MAXLINE + 1), "iso-8859-1")
  File "/usr/lib/python3.9/socket.py", line 704, in readinto
    return self._sock.recv_into(b)
socket.timeout: timed out

The above exception was the direct cause of the following exception:

Traceback (most recent call last):
  File "/app/.venv/lib/python3.9/site-packages/requests/adapters.py", line 667, in send
    resp = conn.urlopen(
  File "/app/.venv/lib/python3.9/site-packages/urllib3/connectionpool.py", line 841, in urlopen
    retries = retries.increment(
  File "/app/.venv/lib/python3.9/site-packages/urllib3/util/retry.py", line 474, in increment
    raise reraise(type(error), error, _stacktrace)
  File "/app/.venv/lib/python3.9/site-packages/urllib3/util/util.py", line 39, in reraise
    raise value
  File "/app/.venv/lib/python3.9/site-packages/urllib3/connectionpool.py", line 787, in urlopen
    response = self._make_request(
  File "/app/.venv/lib/python3.9/site-packages/urllib3/connectionpool.py", line 536, in _make_request
    self._raise_timeout(err=e, url=url, timeout_value=read_timeout)
  File "/app/.venv/lib/python3.9/site-packages/urllib3/connectionpool.py", line 367, in _raise_timeout
    raise ReadTimeoutError(
urllib3.exceptions.ReadTimeoutError: HTTPConnectionPool(host='host.docker.internal', port=9050): Read timed out. (read timeout=5)

During handling of the above exception, another exception occurred:

Traceback (most recent call last):
  File "/app/service.py", line 17, in _request
    resp = requests.post(self.backend_url, json=data,
  File "/app/.venv/lib/python3.9/site-packages/requests/api.py", line 115, in post
    return request("post", url, data=data, json=json, **kwargs)
  File "/app/.venv/lib/python3.9/site-packages/requests/api.py", line 59, in request
    return session.request(method=method, url=url, **kwargs)
  File "/app/.venv/lib/python3.9/site-packages/requests/sessions.py", line 589, in request
    resp = self.send(prep, **send_kwargs)
  File "/app/.venv/lib/python3.9/site-packages/requests/sessions.py", line 703, in send
    r = adapter.send(request, **kwargs)
  File "/app/.venv/lib/python3.9/site-packages/requests/adapters.py", line 713, in send
    raise ReadTimeout(e, request=request)
requests.exceptions.ReadTimeout: HTTPConnectionPool(host='host.docker.internal', port=9050): Read timed out. (read timeout=5)

During handling of the above exception, another exception occurred:

Traceback (most recent call last):
  File "/app/service.py", line 42, in <module>
    service.heartbeat()
  File "/app/service.py", line 35, in heartbeat
    self._request(data)
  File "/app/service.py", line 22, in _request
    raise JudgeServiceError("Heartbeat request failed")
exception.JudgeServiceError
